Workbook

Sheet BI Project Health Check
B2: BI Project Health Check | C2: Self-assessment tool for diagnosing BI Health problems and planning improvements | K2: Designed by Data Nature free to use, comment or share
B3: Answer the questions below one by one and review the charts with the results. These charts show the maturity of your BI project across these factors—plan activities to raise the bars.
B10: (If you are sure that the question is completely non-applicable to your type of organization, leave it unanswered) | H10: 1️⃣ 👇 Answer the questions below one by one and review the charts with the results | L10: 2️⃣ Set your one-year goals for each factor from (0–4) as from the dropdown list.👇
J13: Company | L13: =L33 -> Level 1 | M13: =M33 -> Level 2 | N13: =N33 -> Level 3 | O13: =O33 -> Level 4 | Q13: Target | Y13: Mastering
B14: Connection with business | J14: =J36 -> 1.8333333 | L14: =L36 -> 1.1666667 | M14: =M36 -> 2 | N14: =N36 -> 2.8333333 | O14: =O36 -> 4 | Q14: =Q36 -> 2.6666667 | Y14: 1
B15: Adoption and Satisfaction | J15: =J45 -> 1.4285714 | L15: =L45 -> 0.28571429 | M15: =M45 -> 1.2857143 | N15: =N45 -> 2.2857143 | O15: =O45 -> 3.8571429 | Q15: =Q45 -> 2.1428571 | Y15: 1
B16: BI Content management | J16: =J55 -> 1.3333333 | L16: =L55 -> 0.41666667 | M16: =M55 -> 1.5833333 | N16: =N55 -> 2.9166667 | O16: =O55 -> 4 | Q16: =Q55 -> 2.4285714 | Y16: 1
B17: Self-Service BI Delivery | J17: =J70 -> 1.625 | L17: =L70 -> 0.375 | M17: =M70 -> 1.375 | N17: =N70 -> 3 | O17: =O70 -> 4 | Q17: =Q70 -> 2.5 | Y17: 1
B18: Guided BI Service Delivery | J18: =J81 -> 1.375 | L18: =L81 -> 0.5 | M18: =M81 -> 1.5 | N18: =N81 -> 3 | O18: =O81 -> 4 | Q18: =Q81 -> 2.5 | Y18: 1
B19: BI Platform Governance | J19: =J92 -> 1.2 | L19: =L92 -> 0.5 | M19: =M92 -> 1.5 | N19: =N92 -> 2.8 | O19: =O92 -> 3.8 | Q19: =Q92 -> 1.75 | Y19: 1
B20: Data Quality management | J20: =J105 -> 1 | L20: =L105 -> 1.1666667 | M20: =M105 -> 2 | N20: =N105 -> 3 | O20: =O105 -> 4 | Q20: =Q105 -> 2.3035714 | Y20: 1
B21: BI security and compliance | J21: =J114 -> 1.5 | L21: =L114 -> 0.75 | M21: =M114 -> 1.75 | N21: =N114 -> 3 | O21: =O114 -> 4 | Q21: =Q114 -> 2.125 | Y21: 1
B22: Project Management | J22: =J125 -> 1 | L22: =L125 -> 0.75 | M22: =M125 -> 1.75 | N22: =N125 -> 2.875 | O22: =O125 -> 3.875 | Q22: =Q125 -> 1.75 | Y22: 1
J24: Company | L24: Beginning | M24: Learninig | N24: Developing | O24: Mastering | Q24: Target
B25: Business Alignment | J25: =AVERAGEIF($G$38:$G$262,B25,$J$38:$J$262) -> 2 | L25: =AVERAGEIF($G$38:$G$262,B25,$L$38:$L$262) -> 0.77777778 | M25: =AVERAGEIF($G$38:$G$262,B25,$M$38:$M$262) -> 1.6666667 | N25: =AVERAGEIF($G$38:$G$262,B25,$N$38:$N$262) -> 2.7777778 | O25: =AVERAGEIF($G$38:$G$262,B25,$O$38:$O$262) -> 3.8888889 | Q25: =AVERAGEIF($G$38:$G$262,B25,$Q$38:$Q$262) -> 2.5714286
B26: Data Culture | J26: =AVERAGEIF($G$38:$G$262,B26,$J$38:$J$262) -> 0.66666667 | L26: =AVERAGEIF($G$38:$G$262,B26,$L$38:$L$262) -> 0.625 | M26: =AVERAGEIF($G$38:$G$262,B26,$M$38:$M$262) -> 1.75 | N26: =AVERAGEIF($G$38:$G$262,B26,$N$38:$N$262) -> 2.875 | O26: =AVERAGEIF($G$38:$G$262,B26,$O$38:$O$262) -> 4 | Q26: =AVERAGEIF($G$38:$G$262,B26,$Q$38:$Q$262) -> 2.3333333
B27: Processes & Standards | J27: =AVERAGEIF($G$38:$G$262,B27,$J$38:$J$262) -> 1.0909091 | L27: =AVERAGEIF($G$38:$G$262,B27,$L$38:$L$262) -> 0.85365854 | M27: =AVERAGEIF($G$38:$G$262,B27,$M$38:$M$262) -> 1.8780488 | N27: =AVERAGEIF($G$38:$G$262,B27,$N$38:$N$262) -> 3 | O27: =AVERAGEIF($G$38:$G$262,B27,$O$38:$O$262) -> 4 | Q27: =AVERAGEIF($G$38:$G$262,B27,$Q$38:$Q$262) -> 2.1818182
B28: User Engagement | J28: =AVERAGEIF($G$38:$G$262,B28,$J$38:$J$262) -> 1.7142857 | L28: =AVERAGEIF($G$38:$G$262,B28,$L$38:$L$262) -> 0.42857143 | M28: =AVERAGEIF($G$38:$G$262,B28,$M$38:$M$262) -> 1.2857143 | N28: =AVERAGEIF($G$38:$G$262,B28,$N$38:$N$262) -> 2.4285714 | O28: =AVERAGEIF($G$38:$G$262,B28,$O$38:$O$262) -> 3.8571429 | Q28: =AVERAGEIF($G$38:$G$262,B28,$Q$38:$Q$262) -> 2.2857143
B29: Skills & Trainings | J29: =AVERAGEIF($G$38:$G$262,B29,$J$38:$J$262) -> 1.6666667 | L29: =AVERAGEIF($G$38:$G$262,B29,$L$38:$L$262) -> 0.8 | M29: =AVERAGEIF($G$38:$G$262,B29,$M$38:$M$262) -> 1.9 | N29: =AVERAGEIF($G$38:$G$262,B29,$N$38:$N$262) -> 3 | O29: =AVERAGEIF($G$38:$G$262,B29,$O$38:$O$262) -> 4 | Q29: =AVERAGEIF($G$38:$G$262,B29,$Q$38:$Q$262) -> 2.5
B30: Tools & Automation | J30: =AVERAGEIF($G$38:$G$262,B30,$J$38:$J$262) -> 1.4444444 | L30: =AVERAGEIF($G$38:$G$262,B30,$L$38:$L$262) -> 0.55555556 | M30: =AVERAGEIF($G$38:$G$262,B30,$M$38:$M$262) -> 1.4444444 | N30: =AVERAGEIF($G$38:$G$262,B30,$N$38:$N$262) -> 2.8333333 | O30: =AVERAGEIF($G$38:$G$262,B30,$O$38:$O$262) -> 3.8888889 | Q30: =AVERAGEIF($G$38:$G$262,B30,$Q$38:$Q$262) -> 1.8333333
B31: Efficiency Monitoring | J31: =AVERAGEIF($G$38:$G$262,B31,$J$38:$J$262) -> 1.2857143 | L31: =AVERAGEIF($G$38:$G$262,B31,$L$38:$L$262) -> 0.57142857 | M31: =AVERAGEIF($G$38:$G$262,B31,$M$38:$M$262) -> 1.7142857 | N31: =AVERAGEIF($G$38:$G$262,B31,$N$38:$N$262) -> 3 | O31: =AVERAGEIF($G$38:$G$262,B31,$O$38:$O$262) -> 4 | Q31: =AVERAGEIF($G$38:$G$262,B31,$Q$38:$Q$262) -> 2
B33: List of Factors | G33: Solution category | H33: Your self-estimation | J33: Your score | L33: Level 1 | M33: Level 2 | N33: Level 3 | O33: Level 4 | Q33: 1Y Target
A36: 1 | B36: Connection with business | J36: =AVERAGEIF(J38:J43,">= 0") -> 1.8333333 | L36: =AVERAGEIF(L38:L43,">= 0") -> 1.1666667 | M36: =AVERAGEIF(M38:M43,">= 0") -> 2 | N36: =AVERAGEIF(N38:N43,">= 0") -> 2.8333333 | O36: =AVERAGEIF(O38:O43,">= 0") -> 4 | Q36: =AVERAGEIF(Q38:Q43,">= 0") -> 2.6666667
A38: 1.1 | B38: Registration of analytical cases | C38: Is there a registry of analytical cases, ranked based on their value to the business? | G38: Business Alignment | H38: 3 - Completed, but Improvement Needed | J38: =IFERROR(VLOOKUP(H38,Criteria!B:L,7,0),IFERROR(VLOOKUP(H38,Criteria!C:M,7,0),IFERROR(VLOOKUP(H38,Criteria!D:N,7,0),IFERROR(VLOOKUP(H38,Criteria!E:O,7,0),IFERROR(VLOOKUP(H38,Criteria!F:P,7,0),NA()))))) -> 3 | L38: 0 | M38: 1 | N38: 2 | O38: =4 -> 4 | Q38: 3
A39: 1.2 | B39: Integration into business processes | C39: Are BI reports integrated into regular business processes and meeting cadence for managerial decision-making? | G39: Business Alignment | H39: 3 - Completed, but Improvement Needed | J39: =IFERROR(VLOOKUP(H39,Criteria!B:L,7,0),IFERROR(VLOOKUP(H39,Criteria!C:M,7,0),IFERROR(VLOOKUP(H39,Criteria!D:N,7,0),IFERROR(VLOOKUP(H39,Criteria!E:O,7,0),IFERROR(VLOOKUP(H39,Criteria!F:P,7,0),NA()))))) -> 3 | L39: =1 -> 1 | M39: =2 -> 2 | N39: =3 -> 3 | O39: =4 -> 4 | Q39: 3
A40: 1.3 | B40: Alignment of BI goals with business goals | C40: Do BI initiatives align with the strategic and operational goals of the business? | G40: Business Alignment | H40: 1 - Planned | J40: =IFERROR(VLOOKUP(H40,Criteria!B:L,7,0),IFERROR(VLOOKUP(H40,Criteria!C:M,7,0),IFERROR(VLOOKUP(H40,Criteria!D:N,7,0),IFERROR(VLOOKUP(H40,Criteria!E:O,7,0),IFERROR(VLOOKUP(H40,Criteria!F:P,7,0),NA()))))) -> 1 | L40: 2 | M40: =2 -> 2 | N40: =3 -> 3 | O40: 4 | Q40: 3
A41: 1.4 | B41: Engagement of business leaders | C41: Are business leaders actively involved in BI initiatives and do they promote the dissemination of reports among teams? | G41: Data Culture | H41: 1 - Planned | J41: =IFERROR(VLOOKUP(H41,Criteria!B:L,7,0),IFERROR(VLOOKUP(H41,Criteria!C:M,7,0),IFERROR(VLOOKUP(H41,Criteria!D:N,7,0),IFERROR(VLOOKUP(H41,Criteria!E:O,7,0),IFERROR(VLOOKUP(H41,Criteria!F:P,7,0),NA()))))) -> 1 | L41: 2 | M41: 3 | N41: =3 -> 3 | O41: =4 -> 4 | Q41: 3
A42: 1.5 | B42: Defining target audience roles for BI | C42: Are the personas of the target audience for BI clearly defined and classified by how they consume/produce analytics? | G42: Business Alignment | H42: 2 - In Progress / Partially Completed | J42: =IFERROR(VLOOKUP(H42,Criteria!B:L,7,0),IFERROR(VLOOKUP(H42,Criteria!C:M,7,0),IFERROR(VLOOKUP(H42,Criteria!D:N,7,0),IFERROR(VLOOKUP(H42,Criteria!E:O,7,0),IFERROR(VLOOKUP(H42,Criteria!F:P,7,0),NA()))))) -> 2 | L42: =1 -> 1 | M42: =2 -> 2 | N42: =3 -> 3 | O42: =4 -> 4 | Q42: 2
A43: 1.6 | B43: Structuring business metrics | C43: Is the business metrics tree clearly defined and standardized for organizational consistency? | G43: Processes & Standards | H43: 1 - Planned | J43: =IFERROR(VLOOKUP(H43,Criteria!B:L,7,0),IFERROR(VLOOKUP(H43,Criteria!C:M,7,0),IFERROR(VLOOKUP(H43,Criteria!D:N,7,0),IFERROR(VLOOKUP(H43,Criteria!E:O,7,0),IFERROR(VLOOKUP(H43,Criteria!F:P,7,0),NA()))))) -> 1 | L43: =1 -> 1 | M43: =2 -> 2 | N43: =3 -> 3 | O43: =4 -> 4 | Q43: 2
A45: 2 | B45: Adoption and Satisfaction | J45: =AVERAGEIF(J47:J53,">= 0") -> 1.4285714 | L45: =AVERAGEIF(L47:L53,">= 0") -> 0.28571429 | M45: =AVERAGEIF(M47:M53,">= 0") -> 1.2857143 | N45: =AVERAGEIF(N47:N53,">= 0") -> 2.2857143 | O45: =AVERAGEIF(O47:O53,">= 0") -> 3.8571429 | Q45: =AVERAGEIF(Q47:Q53,">= 0") -> 2.1428571
A47: 2.1 | B47: Monitoring BI usage | C47: Are there tools for monitoring report usage and analyzing BI usage statistics (BI for BI)? | G47: User Engagement | H47: 2 - In Progress / Partially Completed | J47: =IFERROR(VLOOKUP(H47,Criteria!B:L,7,0),IFERROR(VLOOKUP(H47,Criteria!C:M,7,0),IFERROR(VLOOKUP(H47,Criteria!D:N,7,0),IFERROR(VLOOKUP(H47,Criteria!E:O,7,0),IFERROR(VLOOKUP(H47,Criteria!F:P,7,0),NA()))))) -> 2 | L47: 0 | M47: 1 | N47: 2 | O47: 3 | Q47: 2
A48: 2.2 | B48: BI tools adoption assessment | C48: Do you conduct regular assessments of BI/Analytical tools adoption? | G48: User Engagement | H48: 0 - No | J48: =IFERROR(VLOOKUP(H48,Criteria!B:L,7,0),IFERROR(VLOOKUP(H48,Criteria!C:M,7,0),IFERROR(VLOOKUP(H48,Criteria!D:N,7,0),IFERROR(VLOOKUP(H48,Criteria!E:O,7,0),IFERROR(VLOOKUP(H48,Criteria!F:P,7,0),NA()))))) -> 0 | L48: 1 | M48: 2 | N48: 3 | O48: 4 | Q48: 2
A49: 2.3 | B49: Level of business engagement | C49: Does the proportion of active BI users per month exceed 50% for key target management roles? | G49: Data Culture | H49: 1 - Planned | J49: =IFERROR(VLOOKUP(H49,Criteria!B:L,7,0),IFERROR(VLOOKUP(H49,Criteria!C:M,7,0),IFERROR(VLOOKUP(H49,Criteria!D:N,7,0),IFERROR(VLOOKUP(H49,Criteria!E:O,7,0),IFERROR(VLOOKUP(H49,Criteria!F:P,7,0),NA()))))) -> 1 | L49: 0 | M49: 2 | N49: 2 | O49: =4 -> 4 | Q49: 2
A50: 2.4 | B50: BI adoption goals | C50: Is BI/Analytical tools adoption included in the list of goals of the BI Team? | G50: User Engagement | H50: 2 - In Progress / Partially Completed | J50: =IFERROR(VLOOKUP(H50,Criteria!B:L,7,0),IFERROR(VLOOKUP(H50,Criteria!C:M,7,0),IFERROR(VLOOKUP(H50,Criteria!D:N,7,0),IFERROR(VLOOKUP(H50,Criteria!E:O,7,0),IFERROR(VLOOKUP(H50,Criteria!F:P,7,0),NA()))))) -> 2 | L50: 0 | M50: 1 | N50: 2 | O50: =4 -> 4 | Q50: 3
A51: 2.5 | B51: User satisfaction assessment | C51: Are regular user surveys conducted to assess their satisfaction with working with BI reports? | G51: User Engagement | H51: 3 - Completed, but Improvement Needed | J51: =IFERROR(VLOOKUP(H51,Criteria!B:L,7,0),IFERROR(VLOOKUP(H51,Criteria!C:M,7,0),IFERROR(VLOOKUP(H51,Criteria!D:N,7,0),IFERROR(VLOOKUP(H51,Criteria!E:O,7,0),IFERROR(VLOOKUP(H51,Criteria!F:P,7,0),NA()))))) -> 3 | L51: 0 | M51: 0 | N51: 2 | O51: =4 -> 4 | Q51: 2
A52: 2.6 | B52: Feedback gathering | C52: Do you have a framework in place for gathering feedback from end-users to enhance BI reports? | G52: User Engagement | H52: 0 - No | J52: =IFERROR(VLOOKUP(H52,Criteria!B:L,7,0),IFERROR(VLOOKUP(H52,Criteria!C:M,7,0),IFERROR(VLOOKUP(H52,Criteria!D:N,7,0),IFERROR(VLOOKUP(H52,Criteria!E:O,7,0),IFERROR(VLOOKUP(H52,Criteria!F:P,7,0),NA()))))) -> 0 | L52: 0 | M52: 1 | N52: 2 | O52: =4 -> 4 | Q52: 1
A53: 2.7 | B53: Onboarding of new users | C53: Is there a process for onboarding new users into BI tools and systems with recommended reports? | G53: Skills & Trainings | H53: 2 - In Progress / Partially Completed | J53: =IFERROR(VLOOKUP(H53,Criteria!B:L,7,0),IFERROR(VLOOKUP(H53,Criteria!C:M,7,0),IFERROR(VLOOKUP(H53,Criteria!D:N,7,0),IFERROR(VLOOKUP(H53,Criteria!E:O,7,0),IFERROR(VLOOKUP(H53,Criteria!F:P,7,0),NA()))))) -> 2 | L53: 1 | M53: 2 | N53: =3 -> 3 | O53: =4 -> 4 | Q53: 3
A55: 3 | B55: BI Content management | J55: =AVERAGEIF(J57:J68,">= 0") -> 1.3333333 | L55: =AVERAGEIF(L57:L68,">= 0") -> 0.41666667 | M55: =AVERAGEIF(M57:M68,">= 0") -> 1.5833333 | N55: =AVERAGEIF(N57:N68,">= 0") -> 2.9166667 | O55: =AVERAGEIF(O57:O68,">= 0") -> 4 | Q55: =AVERAGEIF(Q57:Q63,">= 0") -> 2.4285714
A57: 3.1 | B57: Acceptance criteria for tasks | C57: Are clear task acceptance criteria defined and agreed upon with the business? | G57: Processes & Standards | H57: 2 - In Progress / Partially Completed | J57: =IFERROR(VLOOKUP(H57,Criteria!B:L,7,0),IFERROR(VLOOKUP(H57,Criteria!C:M,7,0),IFERROR(VLOOKUP(H57,Criteria!D:N,7,0),IFERROR(VLOOKUP(H57,Criteria!E:O,7,0),IFERROR(VLOOKUP(H57,Criteria!F:P,7,0),NA()))))) -> 2 | L57: 0 | M57: =2 -> 2 | N57: =3 -> 3 | O57: =4 -> 4 | Q57: 3
A58: 3.2 | B58: BI development process | C58: Do you have a documented requirements gathering framework? | G58: Processes & Standards | H58: 0 - No | J58: =IFERROR(VLOOKUP(H58,Criteria!B:L,7,0),IFERROR(VLOOKUP(H58,Criteria!C:M,7,0),IFERROR(VLOOKUP(H58,Criteria!D:N,7,0),IFERROR(VLOOKUP(H58,Criteria!E:O,7,0),IFERROR(VLOOKUP(H58,Criteria!F:P,7,0),NA()))))) -> 0 | L58: 0 | M58: 1 | N58: =3 -> 3 | O58: =4 -> 4 | Q58: 3
...

Sheet About the tool
B2: BI Adoption Diagnostics tool by Data Nature | O2: Designed by Data Nature free to use, comment or share
B3: Hey, BI Manager. | O3: https://data-nature.com
B4: This is a tool I developed to streamline the introspection and strategic planning in a simple and clear way. Should this tool not fully meet your needs, feel free to adapt it to your requirements. It's available for free download and customization.
B5: BR, Alex Barakov
B7: Other ideas behind this Tool:
B14: This initiative is open for suggestions from data and analytics community. Feel free to share feedback with comments of write me directly using | J14: Telegram | K14: or | L14: Linkedin
B15: If you require assistance in evaluating data maturity or in designing a data strategy, please feel free to | H15: reach out to me for support.

Sheet Criteria
B2: 0 - No | C2: 1 - Planned | D2: 2 - In Progress / Partially Completed | E2: 3 - Completed, but Improvement Needed | F2: 4 - Fully Completed and Optimized | G2: Select an option | H2: 0 | I2: 1 | J2: 2 | K2: 3 | L2: 4
B3: Up to 50 | C3: Up to 150 | D3: Up to 500 | E3: 500+ | G3: Select an option | H3: 0 | I3: 1 | J3: 2 | K3: 3 | L3: 4
B4: High Dependency: Data is vital for Business | C4: Moderate Dependency: Data provides important support for the business | D4: Low Dependency: Business is managed mostly based on experience and historical practices. | G4: Select an option | H4: 0 | I4: 1 | J4: 2 | K4: 3 | L4: 4
B5: Very Likely: Data-driven innovations are revolutionizing the industry | C5: Somewhat Likely: Moderate impact, with data enhancing existing methods and processes. | D5: Unlikely: Limited influence, traditional approaches remain dominant despite data availability. | G5: Select an option | H5: 0 | I5: 1 | J5: 2 | K5: 3 | L5: 4
B6: Not Applicable | C6: Rarely Applicable | D6: Sometimes Applicable | E6: Often Applicable | F6: Highly Applicable | G6: Select an option | H6: 0 | I6: 1 | J6: 2 | K6: 3 | L6: 4
